<?xml version="1.0" ?>
<robot name="actors">
  <gazebo>
    <plugin filename="liblegged_plugin.so" name="legged_plugin">
      <uri>file://$(find sim_actors)/install/lib</uri>
    </plugin>
<!-- 
  <plugin filename="libvisual_plugin.so" name="traj_plugin">
      <uri>file://$(find sim_actors)/install/lib</uri>
    </plugin>  -->

  </gazebo>

  <gazebo reference="imu_link">
      <sensor name="imu_sensor" type="imu">
      <plugin filename="libgazebo_ros_imu_sensor.so" name="imu_plugin">
          <ros>
            <namespace>/</namespace>
            <remapping>~/out:=imu</remapping>
          </ros>
          <initial_orientation_as_reference>false</initial_orientation_as_reference>
        </plugin>
        <always_on>true</always_on>
        <update_rate>500</update_rate>
        <visualize>true</visualize>
        <imu>
          <angular_velocity>
            <x>
              <noise type="gaussian">
                <mean>0.0</mean>
                <stddev>2e-3</stddev>
                <bias_mean>0.0000075</bias_mean>
                <bias_stddev>0.0000008</bias_stddev>
              </noise>
            </x>
            <y>
              <noise type="gaussian">
                <mean>0.0</mean>
                <stddev>2e-3</stddev><!-- 2e-3-->
                <bias_mean>0.0000075</bias_mean><!--0.0000075 -->
                <bias_stddev>0.0000008</bias_stddev><!--0.0000008-->
              </noise>
            </y>
            <z>
              <noise type="gaussian">
                <mean>0.0</mean>
                <stddev>2e-3</stddev>
                <bias_mean>0.0000075</bias_mean>
                <bias_stddev>0.0000008</bias_stddev>
              </noise>
            </z>
          </angular_velocity>
          <linear_acceleration>
            <x>
              <noise type="gaussian">
                <mean>0.0</mean>
                <stddev>1.7e-2</stddev><!-- 1.7e-2-->
                <bias_mean>0.01</bias_mean>
                <bias_stddev>0.001</bias_stddev><!-- 0.001-->
              </noise>
            </x>
            <y>
              <noise type="gaussian">
                <mean>0.0</mean>
                <stddev>1.7e-2</stddev>
                <bias_mean>0.01</bias_mean>
                <bias_stddev>0.001</bias_stddev>
              </noise>
            </y>
            <z>
              <noise type="gaussian">
                <mean>0.0</mean>
                <stddev>1.7e-2</stddev>
                <bias_mean>0.01</bias_mean>
                <bias_stddev>0.001</bias_stddev>
              </noise>
            </z>
          </linear_acceleration>
        </imu>
      </sensor>
    </gazebo>
  <!-- Foot contacts. -->

  <gazebo reference="base">
    <material>Gazebo/Green</material>
    <turnGravityOff>false</turnGravityOff>
  </gazebo>
  <gazebo reference="body">
    <mu1>0.2</mu1>
    <mu2>0.2</mu2>
    <kp value="50000.0"/>
    <kd value="5000.0"/>
  </gazebo>
  <gazebo reference="stick_link">
    <mu1>0.2</mu1>
    <mu2>0.2</mu2>
    <material>Gazebo/White</material>
  </gazebo>
  <gazebo reference="imu_link">
    <mu1>0.2</mu1>
    <mu2>0.2</mu2>
    <material>Gazebo/Red</material>
  </gazebo>
  <!-- FL leg -->
  <gazebo reference="FL_abad">
    <mu1>0.2</mu1>
    <mu2>0.2</mu2>
    <material>Gazebo/DarkGrey</material>
  </gazebo>
  <gazebo reference="FL_hip">
    <mu1>0.2</mu1>
    <mu2>0.2</mu2>
    <self_collide>1</self_collide>
    <material>Gazebo/DarkGrey</material>
    <kp value="50000.0"/>
    <kd value="5000.0"/>
  </gazebo>
  <gazebo reference="FL_knee">
    <mu1>0.7</mu1>
    <mu2>0.7</mu2>
    <self_collide>1</self_collide>
  </gazebo>
  <gazebo reference="FL_foot">
    <mu1>0.7</mu1>
    <mu2>0.7</mu2>
    <self_collide>1</self_collide>
    <material>Gazebo/DarkGrey</material>
    <kp value="50000.0"/>
    <kd value="5000.0"/>
  </gazebo>
  <!-- FR leg -->
  <gazebo reference="FR_abad">
    <mu1>0.2</mu1>
    <mu2>0.2</mu2>
    <material>Gazebo/DarkGrey</material>
  </gazebo>
  <gazebo reference="FR_hip">
    <mu1>0.2</mu1>
    <mu2>0.2</mu2>
    <self_collide>1</self_collide>
    <material>Gazebo/DarkGrey</material>
    <kp value="50000.0"/>
    <kd value="5000.0"/>
  </gazebo>
  <gazebo reference="FR_knee">
    <mu1>0.2</mu1>
    <mu2>0.2</mu2>
    <self_collide>1</self_collide>
  </gazebo>
  <gazebo reference="FR_foot">
    <mu1>0.7</mu1>
    <mu2>0.7</mu2>
    <self_collide>1</self_collide>
    <material>Gazebo/DarkGrey</material>
    <kp value="50000.0"/>
    <kd value="5000.0"/>
  </gazebo>
  <!-- RL leg -->
  <gazebo reference="RL_abad">
    <mu1>0.2</mu1>
    <mu2>0.2</mu2>
    <material>Gazebo/DarkGrey</material>
  </gazebo>
  <gazebo reference="RL_hip">
    <mu1>0.2</mu1>
    <mu2>0.2</mu2>
    <self_collide>1</self_collide>
    <material>Gazebo/DarkGrey</material>
    <kp value="50000.0"/>
    <kd value="5000.0"/>
  </gazebo>
  <gazebo reference="RL_knee">
    <mu1>0.7</mu1>
    <mu2>0.7</mu2>
    <self_collide>1</self_collide>
    <kp value="5000000000.0"/>
    <kd value="50000.0"/>
  </gazebo>
  <gazebo reference="RL_foot">
    <mu1>0.7</mu1>
    <mu2>0.7</mu2>
    <self_collide>1</self_collide>
    <material>Gazebo/DarkGrey</material>
    <kp value="50000.0"/>
    <kd value="5000.0"/>
  </gazebo>
  <!-- RR leg -->
  <gazebo reference="RR_abad">
    <mu1>0.2</mu1>
    <mu2>0.2</mu2>
    <material>Gazebo/DarkGrey</material>
  </gazebo>
  <gazebo reference="RR_hip">
    <mu1>0.2</mu1>
    <mu2>0.2</mu2>
    <self_collide>1</self_collide>
    <material>Gazebo/DarkGrey</material>
    <kp value="50000.0"/>
    <kd value="5000.0"/>
  </gazebo>
  <gazebo reference="RR_knee">
    <mu1>0.7</mu1>
    <mu2>0.7</mu2>
    <self_collide>1</self_collide>
    <kp value="5000000000.0"/>
    <kd value="50000.0"/>
  </gazebo>
  <gazebo reference="RR_foot">
    <mu1>0.7</mu1>
    <mu2>0.7</mu2>
    <self_collide>1</self_collide>
    <material>Gazebo/DarkGrey</material>
    <kp value="50000.0"/>
    <kd value="5000.0"/>
  </gazebo>

  <link name="base_link">
    <visual>
      <origin rpy="0 0 0" xyz="0 0 0"/>
      <geometry>
        <box size="0.001 0.001 0.001"/>
      </geometry>
    </visual>
  </link>
  <joint name="floating_base" type="fixed">
    <origin rpy="0 0 0" xyz="0 0 0"/>
    <parent link="base_link"/>
    <child link="body"/>
  </joint>
  <link name="body">
    <visual>
      <origin rpy="0 0 0" xyz="0 0 0"/>
      <geometry>
        <mesh filename="package://sim_base/model/meshes/body.dae" scale="1 1 1"/>

      </geometry>
    </visual>
    <collision>
      <origin rpy="0 0 0" xyz="0 0 0"/>
      <geometry>
        <box size="0.236 0.19 0.109"/>
      </geometry>
    </collision>
    <inertial>
      <origin rpy="0 0 0" xyz="0.0273 -0.000242 0.0143"/>
      <mass value = "4.03"/>
      <inertia ixx="0.0185" ixy="-0.000173" ixz="-0.0102" iyy="0.0517" iyz="-2.83e-05" izz="0.0483"/>
    </inertial>
  </link>

  <joint name="imu_joint" type="fixed">
    <parent link="body"/>
    <child link="imu_link"/>
    <origin rpy="0 0 0" xyz="33.4e-3 -17.2765e-3 51.0469e-3"/>
  </joint>


  <link name="imu_link">
    <inertial>
      <mass value="0.001"/>
      <origin rpy="0 0 0" xyz="0 0 0"/>
      <inertia ixx="0.0001" ixy="0" ixz="0" iyy="0.0001" iyz="0" izz="0.0001"/>
    </inertial>
    <visual>
      <origin rpy="0 0 0" xyz="0 0 0"/>
      <geometry>
        <box size="0.001 0.001 0.001"/>
      </geometry>
    </visual>
    <collision>
      <origin rpy="0 0 0" xyz="0 0 0"/>
      <geometry>
        <box size=".001 .001 .001"/>
      </geometry>
    </collision>
  </link>

  <joint name="FR_abad_joint" type="revolute">
    <origin rpy="0 0 0" xyz="0.164 -0.042 0"/>
    <parent link="body"/>
    <child link="FR_abad"/>
    <axis xyz="1 0 0"/>
    <dynamics damping="0.01" friction="0.1"/>
    <limit effort="12.0001" lower="-0.6806784082777885" upper="0.6806784082777885" velocity="30.9971"/>
  </joint>
  <link name="FR_abad">
    <visual>
      <origin rpy="3.141592653589793 0 0" xyz="0 0 0"/>
      <geometry>
        <mesh filename="package://sim_base/model/meshes/abad.dae" scale="1 1 1"/>

      </geometry>
      <material name="orange"/>
    </visual>
    <collision>
      <origin rpy="1.5707963267948966 0 0" xyz="0 0 0"/>
      <geometry>
        <cylinder length="0.035" radius="0.039"/>
      </geometry>
    </collision>
    <inertial>
      <origin rpy="0 0 0" xyz="-0.00392 -0.015 -0.000306"/>
      <mass value="0.354"/>
      <inertia ixx="0.00019" ixy="2.7e-05" ixz="-3.44e-07" iyy="0.000276" iyz="-1.95e-06" izz="0.000233"/>
    </inertial>
  </link>
  <joint name="FR_abad_rotor_fix" type="fixed">
    <origin rpy="0 0 0" xyz="-0.0642303 0 0"/>
    <parent link="FR_abad"/>
    <child link="FR_abad_rotor"/>
  </joint>
  <!-- this link is only for abad rotor inertial -->
  <link name="FR_abad_rotor">
    <inertial>
      <origin rpy="0 0 0" xyz="0 0 0"/>
      <mass value="0.0567"/>
      <inertia ixx="2.53e-05" ixy="0" ixz="0" iyy="4.78e-05" iyz="0" izz="2.53e-05"/>
    </inertial>
  </link>
  <joint name="FR_abad_fixed" type="fixed">
    <origin rpy="0 0 0" xyz="0 -0.059 0"/>
    <parent link="FR_abad"/>
    <child link="FR_hip_shoulder"/>
  </joint>
  <link name="FR_hip_shoulder">
    <collision>
      <origin rpy="1.5707963267948966 0 0" xyz="0 0 0"/>
      <geometry>
        <cylinder length="0.035" radius="0.039"/>
      </geometry>
    </collision>
  </link>
  <joint name="FR_hip_joint" type="revolute">
    <origin rpy="0 0 0" xyz="0 -0.094 0"/>
    <parent link="FR_abad"/>
    <child link="FR_hip"/>
    <axis xyz="0 1 0"/>
    <dynamics damping="0.01" friction="0.1"/>
    <limit effort="12.0001" lower="-1.3264502315156903" upper="2.792526803190927" velocity="30.9971"/>
  </joint>
  <link name="FR_hip">
    <visual>
      <origin rpy="0 0 0" xyz="0 0 0"/>
      <geometry>
        <mesh filename="package://sim_base/model/meshes/hip_mirror.dae" scale="1 1 1"/>

      </geometry>
      <material name="orange"/>
    </visual>
    <collision>
      <origin rpy="0 1.5707963267948966 0" xyz="0 0 -0.06"/>
      <geometry>
        <box size="0.12 0.025 0.034"/>
      </geometry>
    </collision>
    <inertial>
      <origin rpy="0 0 0" xyz="-0.00212 0.0212 -0.0184"/>
      <mass value="0.482"/>
      <inertia ixx="0.00101" ixy="-2.23e-05" ixz="-3.85e-05" iyy="0.000983" iyz="-0.000199" izz="0.000347"/>
    </inertial>
  </link>
  <joint name="FR_hip_rotor_fix" type="fixed">
    <origin rpy="0 0 0" xyz="0 0.07577 0"/>
    <parent link="FR_hip"/>
    <child link="FR_hip_rotor"/>
  </joint>
  <!-- this link is only for hip rotor inertial -->
  <link name="FR_hip_rotor">
    <inertial>
      <origin rpy="0 0 0" xyz="0 0 0"/>
      <mass value="0.0567"/>
      <inertia ixx="2.53e-05" ixy="0" ixz="0" iyy="4.78e-05" iyz="0" izz="2.53e-05"/>
    </inertial>
  </link>
  <joint name="FR_knee_rotor_fix" type="fixed">
    <origin rpy="0 0 0" xyz="0 0.0342303 0"/>
    <parent link="FR_hip"/>
    <child link="FR_knee_rotor"/>
  </joint>
  <!-- this link is only for knee rotor inertial -->
  <link name="FR_knee_rotor">
    <inertial>
      <origin rpy="0 0 0" xyz="0 0 0"/>
      <mass value="0.0567"/>
      <inertia ixx="2.53e-05" ixy="0" ixz="0" iyy="4.78e-05" iyz="0" izz="2.53e-05"/>
    </inertial>
  </link>
  <joint name="FR_knee_joint" type="revolute">
    <origin rpy="0 0 0" xyz="0 0 -0.12"/>
    <parent link="FR_hip"/>
    <child link="FR_knee"/>
    <axis xyz="0 1 0"/>
    <dynamics damping="0.01" friction="0.1"/>
    <limit effort="12.0001" lower="-2.5307274153917776" upper="-0.5235987755982988" velocity="30.9971"/>
  </joint>
  <link name="FR_knee">
    <visual>
      <origin rpy="0 0 0" xyz="0 0 0"/>
      <geometry>
        <mesh filename="package://sim_base/model/meshes/knee.dae" scale="1 1 1"/>

      </geometry>
      <material name="orange"/>
    </visual>
    <collision>
      <origin rpy="0 3.141592653589793 0" xyz="0 0 -0.091705"/>
      <geometry>
        <box size="0.016 0.016 0.18341"/>
      </geometry>
    </collision>
    <collision name="FR_knee_rubber">
      <origin rpy="0 3.141592653589793 0" xyz="-0.01 0 -0.007"/>
      <geometry>
        <sphere radius="0.016"/>
      </geometry>
      <surface>
        <contact>
          <ode>
            <max_vel>0.00001</max_vel>
            <min_depth>0.0</min_depth>
          </ode>
        </contact>
      </surface>
    </collision>
    <inertial>
      <origin rpy="0 0 0" xyz="0.0006 -4.72e-05 -0.0893"/>
      <mass value="0.116"/>
      <inertia ixx="0.000668" ixy="3e-09" ixz="2.37e-05" iyy="0.000674" iyz="6.03e-07" izz="1.54e-05"/>
    </inertial>
  </link>
  <joint name="FR_foot_fixed" type="fixed">
    <origin rpy="0 0 0" xyz="0.0055 0 -0.17390999999999998"/>
    <parent link="FR_knee"/>
    <child link="FR_foot"/>
  </joint>
  <link name="FR_foot">
    <visual>
      <origin rpy="0 0 0" xyz="0 0 0"/>
      <geometry>
        <sphere radius="0.009"/>
      </geometry>
      <material name="orange"/>
    </visual>
    <collision>
      <origin rpy="0 0 0" xyz="0 0 0"/>
      <geometry>
        <sphere radius="0.019"/>
      </geometry>
      <surface>
        <contact>
          <ode>
            <max_vel>0.001</max_vel>
            <min_depth>0.0</min_depth>
          </ode>
        </contact>
      </surface>
    </collision>
  </link>
    <transmission name="FR_abad_tran">
    <type>transmission_interface/SimpleTransmission</type>
    <joint name="FR_abad_joint">
      <hardwareInterface>hardware_interface/EffortJointInterface</hardwareInterface>
    </joint>
    <actuator name="FR_abad_motor">
      <hardwareInterface>hardware_interface/EffortJointInterface</hardwareInterface>
      <mechanicalReduction>&quot;7.75&quot;</mechanicalReduction>
    </actuator>
  </transmission>
  <transmission name="FR_hip_tran">
    <type>transmission_interface/SimpleTransmission</type>
    <joint name="FR_hip_joint">
      <hardwareInterface>hardware_interface/EffortJointInterface</hardwareInterface>
    </joint>
    <actuator name="FR_hip_motor">
      <hardwareInterface>hardware_interface/EffortJointInterface</hardwareInterface>
      <mechanicalReduction>&quot;7.75&quot;</mechanicalReduction>
    </actuator>
  </transmission>
  <transmission name="FR_knee_tran">
    <type>transmission_interface/SimpleTransmission</type>
    <joint name="FR_knee_joint">
      <hardwareInterface>hardware_interface/EffortJointInterface</hardwareInterface>
    </joint>
    <actuator name="FR_knee_motor">
      <hardwareInterface>hardware_interface/EffortJointInterface</hardwareInterface>
      <mechanicalReduction>&quot;7.75&quot;</mechanicalReduction>
    </actuator>
  </transmission>
  <joint name="FL_abad_joint" type="revolute">
    <origin rpy="0 0 0" xyz="0.164 0.042 0"/>
    <parent link="body"/>
    <child link="FL_abad"/>
    <axis xyz="1 0 0"/>
    <dynamics damping="0.01" friction="0.1"/>
    <limit effort="12.0001" lower="-0.6806784082777885" upper="0.6806784082777885" velocity="30.9971"/>
  </joint>
  <link name="FL_abad">
    <visual>
      <origin rpy="0 0 0" xyz="0 0 0"/>
      <geometry>
        <mesh filename="package://sim_base/model/meshes/abad.dae" scale="1 1 1"/>

      </geometry>
      <material name="orange"/>
    </visual>
    <collision>
      <origin rpy="1.5707963267948966 0 0" xyz="0 0 0"/>
      <geometry>
        <cylinder length="0.035" radius="0.039"/>
      </geometry>
    </collision>
    <inertial>
      <origin rpy="0 0 0" xyz="-0.00392 0.015 -0.000306"/>
      <mass value="0.354"/>
      <inertia ixx="0.00019" ixy="-2.7e-05" ixz="-3.44e-07" iyy="0.000276" iyz="1.95e-06" izz="0.000233"/>
    </inertial>
  </link>
  <joint name="FL_abad_rotor_fix" type="fixed">
    <origin rpy="0 0 0" xyz="-0.0642303 0 0"/>
    <parent link="FL_abad"/>
    <child link="FL_abad_rotor"/>
  </joint>
  <!-- this link is only for abad rotor inertial -->
  <link name="FL_abad_rotor">
    <inertial>
      <origin rpy="0 0 0" xyz="0 0 0"/>
      <mass value="0.0567"/>
      <inertia ixx="2.53e-05" ixy="0" ixz="0" iyy="4.78e-05" iyz="0" izz="2.53e-05"/>
    </inertial>
  </link>
  <joint name="FL_abad_fixed" type="fixed">
    <origin rpy="0 0 0" xyz="0 0.059 0"/>
    <parent link="FL_abad"/>
    <child link="FL_hip_shoulder"/>
  </joint>
  <link name="FL_hip_shoulder">
    <collision>
      <origin rpy="1.5707963267948966 0 0" xyz="0 0 0"/>
      <geometry>
        <cylinder length="0.035" radius="0.039"/>
      </geometry>
    </collision>
  </link>
  <joint name="FL_hip_joint" type="revolute">
    <origin rpy="0 0 0" xyz="0 0.094 0"/>
    <parent link="FL_abad"/>
    <child link="FL_hip"/>
    <axis xyz="0 1 0"/>
    <dynamics damping="0.01" friction="0.1"/>
    <limit effort="12.0001" lower="-1.3264502315156903" upper="2.792526803190927" velocity="30.9971"/>
  </joint>
  <link name="FL_hip">
    <visual>
      <origin rpy="0 0 0" xyz="0 0 0"/>
      <geometry>
        <mesh filename="package://sim_base/model/meshes/hip.dae" scale="1 1 1"/>

      </geometry>
      <material name="orange"/>
    </visual>
    <collision>
      <origin rpy="0 1.5707963267948966 0" xyz="0 0 -0.06"/>
      <geometry>
        <box size="0.12 0.025 0.034"/>
      </geometry>
    </collision>
    <inertial>
      <origin rpy="0 0 0" xyz="-0.00212 -0.0212 -0.0184"/>
      <mass value="0.482"/>
      <inertia ixx="0.00101" ixy="2.23e-05" ixz="-3.85e-05" iyy="0.000983" iyz="0.000199" izz="0.000347"/>
    </inertial>
  </link>
  <joint name="FL_hip_rotor_fix" type="fixed">
    <origin rpy="0 0 0" xyz="0 -0.07577 0"/>
    <parent link="FL_hip"/>
    <child link="FL_hip_rotor"/>
  </joint>
  <!-- this link is only for hip rotor inertial -->
  <link name="FL_hip_rotor">
    <inertial>
      <origin rpy="0 0 0" xyz="0 0 0"/>
      <mass value="0.0567"/>
      <inertia ixx="2.53e-05" ixy="0" ixz="0" iyy="4.78e-05" iyz="0" izz="2.53e-05"/>
    </inertial>
  </link>
  <joint name="FL_knee_rotor_fix" type="fixed">
    <origin rpy="0 0 0" xyz="0 -0.0342303 0"/>
    <parent link="FL_hip"/>
    <child link="FL_knee_rotor"/>
  </joint>
  <!-- this link is only for knee rotor inertial -->
  <link name="FL_knee_rotor">
    <inertial>
      <origin rpy="0 0 0" xyz="0 0 0"/>
      <mass value="0.0567"/>
      <inertia ixx="2.53e-05" ixy="0" ixz="0" iyy="4.78e-05" iyz="0" izz="2.53e-05"/>
    </inertial>
  </link>
  <joint name="FL_knee_joint" type="revolute">
    <origin rpy="0 0 0" xyz="0 0 -0.12"/>
    <parent link="FL_hip"/>
    <child link="FL_knee"/>
    <axis xyz="0 1 0"/>
    <dynamics damping="0.01" friction="0.1"/>
    <limit effort="12.0001" lower="-2.5307274153917776" upper="-0.5235987755982988" velocity="30.9971"/>
  </joint>
  <link name="FL_knee">
    <visual>
      <origin rpy="0 0 0" xyz="0 0 0"/>
      <geometry>
        <mesh filename="package://sim_base/model/meshes/knee.dae" scale="1 1 1"/>

      </geometry>
      <material name="orange"/>
    </visual>
    <collision>
      <origin rpy="0 3.141592653589793 0" xyz="0 0 -0.091705"/>
      <geometry>
        <box size="0.016 0.016 0.18341"/>
      </geometry>
    </collision>
    <collision name="FL_knee_rubber">
      <origin rpy="0 3.141592653589793 0" xyz="-0.01 0 -0.007"/>
      <geometry>
        <sphere radius="0.016"/>
      </geometry>
      <surface>
        <contact>
          <ode>
            <max_vel>0.00001</max_vel>
            <min_depth>0.0</min_depth>
          </ode>
        </contact>
      </surface>
    </collision>
    <inertial>
      <origin rpy="0 0 0" xyz="0.0006 -4.72e-05 -0.0893"/>
      <mass value="0.116"/>
      <inertia ixx="0.000668" ixy="3e-09" ixz="2.37e-05" iyy="0.000674" iyz="6.03e-07" izz="1.54e-05"/>
    </inertial>
  </link>
  <joint name="FL_foot_fixed" type="fixed">
    <origin rpy="0 0 0" xyz="0.0055 0 -0.17390999999999998"/>
    <parent link="FL_knee"/>
    <child link="FL_foot"/>
  </joint>
  <link name="FL_foot">
    <visual>
      <origin rpy="0 0 0" xyz="0 0 0"/>
      <geometry>
        <sphere radius="0.009"/>
      </geometry>
      <material name="orange"/>
    </visual>
    <collision>
      <origin rpy="0 0 0" xyz="0 0 0"/>
      <geometry>
        <sphere radius="0.019"/>
      </geometry>
      <surface>
        <contact>
          <ode>
            <max_vel>0.001</max_vel>
            <min_depth>0.0</min_depth>
          </ode>
        </contact>
      </surface>
    </collision>
  </link>
  <transmission name="FL_abad_tran">
    <type>transmission_interface/SimpleTransmission</type>
    <joint name="FL_abad_joint">
      <hardwareInterface>hardware_interface/EffortJointInterface</hardwareInterface>
    </joint>
    <actuator name="FL_abad_motor">
      <hardwareInterface>hardware_interface/EffortJointInterface</hardwareInterface>
      <mechanicalReduction>&quot;7.75&quot;</mechanicalReduction>
    </actuator>
  </transmission>
  <transmission name="FL_hip_tran">
    <type>transmission_interface/SimpleTransmission</type>
    <joint name="FL_hip_joint">
      <hardwareInterface>hardware_interface/EffortJointInterface</hardwareInterface>
    </joint>
    <actuator name="FL_hip_motor">
      <hardwareInterface>hardware_interface/EffortJointInterface</hardwareInterface>
      <mechanicalReduction>&quot;7.75&quot;</mechanicalReduction>
    </actuator>
  </transmission>
  <transmission name="FL_knee_tran">
    <type>transmission_interface/SimpleTransmission</type>
    <joint name="FL_knee_joint">
      <hardwareInterface>hardware_interface/EffortJointInterface</hardwareInterface>
    </joint>
    <actuator name="FL_knee_motor">
      <hardwareInterface>hardware_interface/EffortJointInterface</hardwareInterface>
      <mechanicalReduction>&quot;7.75&quot;</mechanicalReduction>
    </actuator>
  </transmission>
  <joint name="RR_abad_joint" type="revolute">
    <origin rpy="0 0 0" xyz="-0.164 -0.042 0"/>
    <parent link="body"/>
    <child link="RR_abad"/>
    <axis xyz="1 0 0"/>
    <dynamics damping="0.01" friction="0.1"/>
    <limit effort="12.0001" lower="-0.6806784082777885" upper="0.6806784082777885" velocity="30.9971"/>
  </joint>
  <link name="RR_abad">
    <visual>
      <origin rpy="3.141592653589793 3.141592653589793 0" xyz="0 0 0"/>
      <geometry>
        <mesh filename="package://sim_base/model/meshes/abad.dae" scale="1 1 1"/>

      </geometry>
      <material name="orange"/>
    </visual>
    <collision>
      <origin rpy="1.5707963267948966 0 0" xyz="0 0 0"/>
      <geometry>
        <cylinder length="0.035" radius="0.039"/>
      </geometry>
    </collision>
    <inertial>
      <origin rpy="0 0 0" xyz="0.00392 -0.015 -0.000306"/>
      <mass value="0.354"/>
      <inertia ixx="0.00019" ixy="-2.7e-05" ixz="3.44e-07" iyy="0.000276" iyz="-1.95e-06" izz="0.000233"/>
    </inertial>
  </link>
  <joint name="RR_abad_rotor_fix" type="fixed">
    <origin rpy="0 0 0" xyz="0.0642303 0 0"/>
    <parent link="RR_abad"/>
    <child link="RR_abad_rotor"/>
  </joint>
  <!-- this link is only for abad rotor inertial -->
  <link name="RR_abad_rotor">
    <inertial>
      <origin rpy="0 0 0" xyz="0 0 0"/>
      <mass value="0.0567"/>
      <inertia ixx="2.53e-05" ixy="0" ixz="0" iyy="4.78e-05" iyz="0" izz="2.53e-05"/>
    </inertial>
  </link>
  <joint name="RR_abad_fixed" type="fixed">
    <origin rpy="0 0 0" xyz="0 -0.059 0"/>
    <parent link="RR_abad"/>
    <child link="RR_hip_shoulder"/>
  </joint>
  <link name="RR_hip_shoulder">
    <collision>
      <origin rpy="1.5707963267948966 0 0" xyz="0 0 0"/>
      <geometry>
        <cylinder length="0.035" radius="0.039"/>
      </geometry>
    </collision>
  </link>
  <joint name="RR_hip_joint" type="revolute">
    <origin rpy="0 0 0" xyz="0 -0.094 0"/>
    <parent link="RR_abad"/>
    <child link="RR_hip"/>
    <axis xyz="0 1 0"/>
    <dynamics damping="0.01" friction="0.1"/>
    <limit effort="12.0001" lower="-0.9773843811168246" upper="3.141592653589793" velocity="30.9971"/>
  </joint>
  <link name="RR_hip">
    <visual>
      <origin rpy="0 0 0" xyz="0 0 0"/>
      <geometry>
        <mesh filename="package://sim_base/model/meshes/hip_mirror.dae" scale="1 1 1"/>

      </geometry>
      <material name="orange"/>
    </visual>
    <collision>
      <origin rpy="0 1.5707963267948966 0" xyz="0 0 -0.06"/>
      <geometry>
        <box size="0.12 0.025 0.034"/>
      </geometry>
    </collision>
    <inertial>
      <origin rpy="0 0 0" xyz="-0.00212 0.0212 -0.0184"/>
      <mass value="0.482"/>
      <inertia ixx="0.00101" ixy="-2.23e-05" ixz="-3.85e-05" iyy="0.000983" iyz="-0.000199" izz="0.000347"/>
    </inertial>
  </link>
  <joint name="RR_hip_rotor_fix" type="fixed">
    <origin rpy="0 0 0" xyz="0 0.07577 0"/>
    <parent link="RR_hip"/>
    <child link="RR_hip_rotor"/>
  </joint>
  <!-- this link is only for hip rotor inertial -->
  <link name="RR_hip_rotor">
    <inertial>
      <origin rpy="0 0 0" xyz="0 0 0"/>
      <mass value="0.0567"/>
      <inertia ixx="2.53e-05" ixy="0" ixz="0" iyy="4.78e-05" iyz="0" izz="2.53e-05"/>
    </inertial>
  </link>
  <joint name="RR_knee_rotor_fix" type="fixed">
    <origin rpy="0 0 0" xyz="0 0.0342303 0"/>
    <parent link="RR_hip"/>
    <child link="RR_knee_rotor"/>
  </joint>
  <!-- this link is only for knee rotor inertial -->
  <link name="RR_knee_rotor">
    <inertial>
      <origin rpy="0 0 0" xyz="0 0 0"/>
      <mass value="0.0567"/>
      <inertia ixx="2.53e-05" ixy="0" ixz="0" iyy="4.78e-05" iyz="0" izz="2.53e-05"/>
    </inertial>
  </link>
  <joint name="RR_knee_joint" type="revolute">
    <origin rpy="0 0 0" xyz="0 0 -0.12"/>
    <parent link="RR_hip"/>
    <child link="RR_knee"/>
    <axis xyz="0 1 0"/>
    <dynamics damping="0.01" friction="0.1"/>
    <limit effort="12.0001" lower="-2.5307274153917776" upper="-0.5235987755982988" velocity="30.9971"/>
  </joint>
  <link name="RR_knee">
    <visual>
      <origin rpy="0 0 0" xyz="0 0 0"/>
      <geometry>
        <mesh filename="package://sim_base/model/meshes/knee.dae" scale="1 1 1"/>

      </geometry>
      <material name="orange"/>
    </visual>
    <collision>
      <origin rpy="0 3.141592653589793 0" xyz="0 0 -0.091705"/>
      <geometry>
        <box size="0.016 0.016 0.18341"/>
      </geometry>
    </collision>
    <collision name="RR_knee_rubber">
      <origin rpy="0 3.141592653589793 0" xyz="-0.01 0 -0.007"/>
      <geometry>
        <sphere radius="0.016"/>
      </geometry>
      <surface>
        <contact>
          <ode>
            <max_vel>0.00001</max_vel>
            <min_depth>0.0</min_depth>
          </ode>
        </contact>
      </surface>
    </collision>
    <inertial>
      <origin rpy="0 0 0" xyz="0.0006 -4.72e-05 -0.0893"/>
      <mass value="0.116"/>
      <inertia ixx="0.000668" ixy="3e-09" ixz="2.37e-05" iyy="0.000674" iyz="6.03e-07" izz="1.54e-05"/>
    </inertial>
  </link>
  <joint name="RR_foot_fixed" type="fixed">
    <origin rpy="0 0 0" xyz="0.0055 0 -0.17390999999999998"/>
    <parent link="RR_knee"/>
    <child link="RR_foot"/>
  </joint>
  <link name="RR_foot">
    <visual>
      <origin rpy="0 0 0" xyz="0 0 0"/>
      <geometry>
        <sphere radius="0.009"/>
      </geometry>
      <material name="orange"/>
    </visual>
    <collision>
      <origin rpy="0 0 0" xyz="0 0 0"/>
      <geometry>
        <sphere radius="0.019"/>
      </geometry>
      <surface>
        <contact>
          <ode>
            <max_vel>0.001</max_vel>
            <min_depth>0.0</min_depth>
          </ode>
        </contact>
      </surface>
    </collision>
  </link>
  <transmission name="RR_abad_tran">
    <type>transmission_interface/SimpleTransmission</type>
    <joint name="RR_abad_joint">
      <hardwareInterface>hardware_interface/EffortJointInterface</hardwareInterface>
    </joint>
    <actuator name="RR_abad_motor">
      <hardwareInterface>hardware_interface/EffortJointInterface</hardwareInterface>
      <mechanicalReduction>&quot;7.75&quot;</mechanicalReduction>
    </actuator>
  </transmission>
  <transmission name="RR_hip_tran">
    <type>transmission_interface/SimpleTransmission</type>
    <joint name="RR_hip_joint">
      <hardwareInterface>hardware_interface/EffortJointInterface</hardwareInterface>
    </joint>
    <actuator name="RR_hip_motor">
      <hardwareInterface>hardware_interface/EffortJointInterface</hardwareInterface>
      <mechanicalReduction>&quot;7.75&quot;</mechanicalReduction>
    </actuator>
  </transmission>
  <transmission name="RR_knee_tran">
    <type>transmission_interface/SimpleTransmission</type>
    <joint name="RR_knee_joint">
      <hardwareInterface>hardware_interface/EffortJointInterface</hardwareInterface>
    </joint>
    <actuator name="RR_knee_motor">
      <hardwareInterface>hardware_interface/EffortJointInterface</hardwareInterface>
      <mechanicalReduction>&quot;7.75&quot;</mechanicalReduction>
    </actuator>
  </transmission>
  <joint name="RL_abad_joint" type="revolute">
    <origin rpy="0 0 0" xyz="-0.164 0.042 0"/>
    <parent link="body"/>
    <child link="RL_abad"/>
    <axis xyz="1 0 0"/>
    <dynamics damping="0.01" friction="0.1"/>
    <limit effort="12.0001" lower="-0.6806784082777885" upper="0.6806784082777885" velocity="30.9971"/>
  </joint>
  <link name="RL_abad">
    <visual>
      <origin rpy="0 3.141592653589793 0" xyz="0 0 0"/>
      <geometry>
        <mesh filename="package://sim_base/model/meshes/abad.dae" scale="1 1 1"/>

      </geometry>
      <material name="orange"/>
    </visual>
    <collision>
      <origin rpy="1.5707963267948966 0 0" xyz="0 0 0"/>
      <geometry>
        <cylinder length="0.035" radius="0.039"/>
      </geometry>
    </collision>
    <inertial>
      <origin rpy="0 0 0" xyz="0.00392 0.015 -0.000306"/>
      <mass value="0.354"/>
      <inertia ixx="0.00019" ixy="2.7e-05" ixz="3.44e-07" iyy="0.000276" iyz="1.95e-06" izz="0.000233"/>
    </inertial>
  </link>
  <joint name="RL_abad_rotor_fix" type="fixed">
    <origin rpy="0 0 0" xyz="0.0642303 0 0"/>
    <parent link="RL_abad"/>
    <child link="RL_abad_rotor"/>
  </joint>
  <!-- this link is only for abad rotor inertial -->
  <link name="RL_abad_rotor">
    <inertial>
      <origin rpy="0 0 0" xyz="0 0 0"/>
      <mass value="0.0567"/>
      <inertia ixx="2.53e-05" ixy="0" ixz="0" iyy="4.78e-05" iyz="0" izz="2.53e-05"/>
    </inertial>
  </link>
  <joint name="RL_abad_fixed" type="fixed">
    <origin rpy="0 0 0" xyz="0 0.059 0"/>
    <parent link="RL_abad"/>
    <child link="RL_hip_shoulder"/>
  </joint>
  <link name="RL_hip_shoulder">
    <collision>
      <origin rpy="1.5707963267948966 0 0" xyz="0 0 0"/>
      <geometry>
        <cylinder length="0.035" radius="0.039"/>
      </geometry>
    </collision>
  </link>
  <joint name="RL_hip_joint" type="revolute">
    <origin rpy="0 0 0" xyz="0 0.094 0"/>
    <parent link="RL_abad"/>
    <child link="RL_hip"/>
    <axis xyz="0 1 0"/>
    <dynamics damping="0.01" friction="0.1"/>
    <limit effort="12.0001" lower="-0.9773843811168246" upper="3.141592653589793" velocity="30.9971"/>
  </joint>
  <link name="RL_hip">
    <visual>
      <origin rpy="0 0 0" xyz="0 0 0"/>
      <geometry>
        <mesh filename="package://sim_base/model/meshes/hip.dae" scale="1 1 1"/>

      </geometry>
      <material name="orange"/>
    </visual>
    <collision>
      <origin rpy="0 1.5707963267948966 0" xyz="0 0 -0.06"/>
      <geometry>
        <box size="0.12 0.025 0.034"/>
      </geometry>
    </collision>
    <inertial>
      <origin rpy="0 0 0" xyz="-0.00212 -0.0212 -0.0184"/>
      <mass value="0.482"/>
      <inertia ixx="0.00101" ixy="2.23e-05" ixz="-3.85e-05" iyy="0.000983" iyz="0.000199" izz="0.000347"/>
    </inertial>
  </link>
  <joint name="RL_hip_rotor_fix" type="fixed">
    <origin rpy="0 0 0" xyz="0 -0.07577 0"/>
    <parent link="RL_hip"/>
    <child link="RL_hip_rotor"/>
  </joint>
  <!-- this link is only for hip rotor inertial -->
  <link name="RL_hip_rotor">
    <inertial>
      <origin rpy="0 0 0" xyz="0 0 0"/>
      <mass value="0.0567"/>
      <inertia ixx="2.53e-05" ixy="0" ixz="0" iyy="4.78e-05" iyz="0" izz="2.53e-05"/>
    </inertial>
  </link>
  <joint name="RL_knee_rotor_fix" type="fixed">
    <origin rpy="0 0 0" xyz="0 -0.0342303 0"/>
    <parent link="RL_hip"/>
    <child link="RL_knee_rotor"/>
  </joint>
  <!-- this link is only for knee rotor inertial -->
  <link name="RL_knee_rotor">
    <inertial>
      <origin rpy="0 0 0" xyz="0 0 0"/>
      <mass value="0.0567"/>
      <inertia ixx="2.53e-05" ixy="0" ixz="0" iyy="4.78e-05" iyz="0" izz="2.53e-05"/>
    </inertial>
  </link>
  <joint name="RL_knee_joint" type="revolute">
    <origin rpy="0 0 0" xyz="0 0 -0.12"/>
    <parent link="RL_hip"/>
    <child link="RL_knee"/>
    <axis xyz="0 1 0"/>
    <dynamics damping="0.01" friction="0.1"/>
    <limit effort="12.0001" lower="-2.5307274153917776" upper="-0.5235987755982988" velocity="30.9971"/>
  </joint>
  <link name="RL_knee">
    <visual>
      <origin rpy="0 0 0" xyz="0 0 0"/>
      <geometry>
        <mesh filename="package://sim_base/model/meshes/knee.dae" scale="1 1 1"/>

      </geometry>
      <material name="orange"/>
    </visual>
    <collision>
      <origin rpy="0 3.141592653589793 0" xyz="0 0 -0.091705"/>
      <geometry>
        <box size="0.016 0.016 0.18341"/>
      </geometry>
    </collision>
    <collision name="RL_knee_rubber">
      <origin rpy="0 3.141592653589793 0" xyz="-0.01 0 -0.007"/>
      <geometry>
        <sphere radius="0.016"/>
      </geometry>
      <surface>
        <contact>
          <ode>
            <max_vel>0.00001</max_vel>
            <min_depth>0.0</min_depth>
          </ode>
        </contact>
      </surface>
    </collision>
    <inertial>
      <origin rpy="0 0 0" xyz="0.0006 -4.72e-05 -0.0893"/>
      <mass value="0.116"/>
      <inertia ixx="0.000668" ixy="3e-09" ixz="2.37e-05" iyy="0.000674" iyz="6.03e-07" izz="1.54e-05"/>
    </inertial>
  </link>
  <joint name="RL_foot_fixed" type="fixed">
    <origin rpy="0 0 0" xyz="0.0055 0 -0.17390999999999998"/>
    <parent link="RL_knee"/>
    <child link="RL_foot"/>
  </joint>
  <link name="RL_foot">
    <visual>
      <origin rpy="0 0 0" xyz="0 0 0"/>
      <geometry>
        <sphere radius="0.009"/>
      </geometry>
      <material name="orange"/>
    </visual>
    <collision>
      <origin rpy="0 0 0" xyz="0 0 0"/>
      <geometry>
        <sphere radius="0.019"/>
      </geometry>
      <surface>
        <contact>
          <ode>
            <max_vel>0.001</max_vel>
            <min_depth>0.0</min_depth>
          </ode>
        </contact>
      </surface>
    </collision>
  </link>
  <transmission name="RL_abad_tran">
    <type>transmission_interface/SimpleTransmission</type>
    <joint name="RL_abad_joint">
      <hardwareInterface>hardware_interface/EffortJointInterface</hardwareInterface>
    </joint>
    <actuator name="RL_abad_motor">
      <hardwareInterface>hardware_interface/EffortJointInterface</hardwareInterface>
      <mechanicalReduction>&quot;7.75&quot;</mechanicalReduction>
    </actuator>
  </transmission>
  <transmission name="RL_hip_tran">
    <type>transmission_interface/SimpleTransmission</type>
    <joint name="RL_hip_joint">
      <hardwareInterface>hardware_interface/EffortJointInterface</hardwareInterface>
    </joint>
    <actuator name="RL_hip_motor">
      <hardwareInterface>hardware_interface/EffortJointInterface</hardwareInterface>
      <mechanicalReduction>&quot;7.75&quot;</mechanicalReduction>
    </actuator>
  </transmission>
  <transmission name="RL_knee_tran">
    <type>transmission_interface/SimpleTransmission</type>
    <joint name="RL_knee_joint">
      <hardwareInterface>hardware_interface/EffortJointInterface</hardwareInterface>
    </joint>
    <actuator name="RL_knee_motor">
      <hardwareInterface>hardware_interface/EffortJointInterface</hardwareInterface>
      <mechanicalReduction>&quot;7.75&quot;</mechanicalReduction>
    </actuator>
  </transmission>
  <!-- This link is only for head collision -->
  <joint name="head_joint" type="fixed">
    <parent link="body"/>
    <child link="head"/>
    <origin rpy="0 0 0" xyz="0 0 0"/>
  </joint>
  <link name="head">
    <collision>
      <origin rpy="0 0 0" xyz="0.256 0 0.120"/>
      <geometry>
        <box size="0.076 0.060 0.040"/>
      </geometry>
    </collision>
    <collision>
      <origin rpy="0 0 0" xyz="0.225 0 0.150"/>
      <geometry>
        <box size="0.020 0.080 0.100"/>
      </geometry>
    </collision>
  </link>
</robot>
